Workbook

Sheet Summary Report 
A1: QA TEST SUMMARY REPORT
A3: Project Name: | B3: Restful Booker API
A4: Test Cycle: | B4: Automation Testing
A5: Execution Date: | B5: 46254
A6: QA Lead: | B6: Group1
B8: Run Summary
B9: Total Run | C9: Pass | D9: Failed
B10: 161 | C10: 125 | D10: 36
B11: Error | C11: Duration | D11: Avg.Response
B12: 0 | C12: 23s 318ms | D12: 768ms
A15: Overall Execution Metrics | E15: Defect Profile By Severity
A16: Metric Status | B16: Count | C16: Percentage | E16: Severity | F16: Open Defects | G16: Closed Defects | H16: Total Defects
A17: Passed Tests | B17: =COUNTIF('API Test Cases'!M:M, "Pass") -> 67 | C17: =B17/B20 -> 0.69072165 | E17: High | F17: =COUNTIF('Bug Report '!K:K,'Summary Report '!E17) -> 7 | G17: 0 | H17: =F17+G17 -> 7
A18: Failed Tests | B18: =COUNTIF('API Test Cases'!M:M, "Fail") -> 30 | C18: =B18/B20 -> 0.30927835 | E18: Medium | F18: =COUNTIF('Bug Report '!K:K,'Summary Report '!E18) -> 8 | G18: 0 | H18: =F18+G18 -> 8
A19: Blocked Tests | B19: 0 | C19: =B19/B20 -> 0 | E19: Low | F19: =COUNTIF('Bug Report '!K:K,'Summary Report '!E19) -> 3 | G19: 0 | H19: =F19+G19 -> 3
A20: Total Test Cases | B20: =SUM(B17:B19) -> 97 | C20: =SUM(C17:C19) -> 1 | E20: Total Defects | F20: =SUM(F17:F19) -> 18 | G20: =SUM(G17:G19) -> 0 | H20: =SUM(H17:H19) -> 18
A23: Module / Feature | B23: Total Cases | C23: Passed | D23: Faild | E23: Pass Rate
A24: Booking Retrieval | B24: =COUNTIFS('API Test Cases'!B:B,Table110[[#This Row],[Module / Feature]]) -> 28 | C24: =COUNTIFS('API Test Cases'!B:B,Table110[[#This Row],[Module / Feature]],'API Test Cases'!M:M,"Pass") -> 25 | D24: =COUNTIFS('API Test Cases'!B:B,Table110[[#This Row],[Module / Feature]],'API Test Cases'!M:M,"Fail") -> 3 | E24: =C24/$B$32 -> 0.25773196
A25: Booking Update | B25: =COUNTIFS('API Test Cases'!B:B,Table110[[#This Row],[Module / Feature]]) -> 22 | C25: =COUNTIFS('API Test Cases'!B:B,Table110[[#This Row],[Module / Feature]],'API Test Cases'!M:M,"Pass") -> 19 | D25: =COUNTIFS('API Test Cases'!B:B,Table110[[#This Row],[Module / Feature]],'API Test Cases'!M:M,"Fail") -> 3 | E25: =C25/$B$32 -> 0.19587629
A26: Booking Deletion | B26: =COUNTIFS('API Test Cases'!B:B,Table110[[#This Row],[Module / Feature]]) -> 8 | C26: =COUNTIFS('API Test Cases'!B:B,Table110[[#This Row],[Module / Feature]],'API Test Cases'!M:M,"Pass") -> 7 | D26: =COUNTIFS('API Test Cases'!B:B,Table110[[#This Row],[Module / Feature]],'API Test Cases'!M:M,"Fail") -> 1 | E26: =C26/$B$32 -> 0.072164948
A27: Health Check | B27: =COUNTIFS('API Test Cases'!B:B,Table110[[#This Row],[Module / Feature]]) -> 1 | C27: =COUNTIFS('API Test Cases'!B:B,Table110[[#This Row],[Module / Feature]],'API Test Cases'!M:M,"Pass") -> 1 | D27: =COUNTIFS('API Test Cases'!B:B,Table110[[#This Row],[Module / Feature]],'API Test Cases'!M:M,"Fail") -> 0 | E27: =C27/$B$32 -> 0.010309278
A28: End-to-End | B28: =COUNTIFS('API Test Cases'!B:B,Table110[[#This Row],[Module / Feature]]) -> 2 | C28: =COUNTIFS('API Test Cases'!B:B,Table110[[#This Row],[Module / Feature]],'API Test Cases'!M:M,"Pass") -> 2 | D28: =COUNTIFS('API Test Cases'!B:B,Table110[[#This Row],[Module / Feature]],'API Test Cases'!M:M,"Fail") -> 0 | E28: =C28/$B$32 -> 0.020618557
A29: Ping Testing | B29: =COUNTIFS('API Test Cases'!B:B,Table110[[#This Row],[Module / Feature]]) -> 5 | C29: =COUNTIFS('API Test Cases'!B:B,Table110[[#This Row],[Module / Feature]],'API Test Cases'!M:M,"Pass") -> 5 | D29: =COUNTIFS('API Test Cases'!B:B,Table110[[#This Row],[Module / Feature]],'API Test Cases'!M:M,"Fail") -> 0 | E29: =C29/$B$32 -> 0.051546392
A30: Auth - POST /auth | B30: =COUNTIFS('API Test Cases'!B:B,Table110[[#This Row],[Module / Feature]]) -> 12 | C30: =COUNTIFS('API Test Cases'!B:B,Table110[[#This Row],[Module / Feature]],'API Test Cases'!M:M,"Pass") -> 3 | D30: =COUNTIFS('API Test Cases'!B:B,Table110[[#This Row],[Module / Feature]],'API Test Cases'!M:M,"Fail") -> 9 | E30: =C30/$B$32 -> 0.030927835
A31: Booking - POST /booking | B31: =COUNTIFS('API Test Cases'!B:B,Table110[[#This Row],[Module / Feature]]) -> 19 | C31: =COUNTIFS('API Test Cases'!B:B,Table110[[#This Row],[Module / Feature]],'API Test Cases'!M:M,"Pass") -> 5 | D31: =COUNTIFS('API Test Cases'!B:B,Table110[[#This Row],[Module / Feature]],'API Test Cases'!M:M,"Fail") -> 14 | E31: =C31/$B$32 -> 0.051546392
B32: =SUBTOTAL(109,Table110[Total Cases]) -> 97 | C32: =SUBTOTAL(109,Table110[Passed]) -> 67 | D32: =SUBTOTAL(109,Table110[Faild]) -> 30 | E32: =C32/B32 -> 0.69072165

Sheet API Test Cases
A1: Test Case ID | B1: Module / Endpoint | C1: Test Scenario | D1: Test Type | E1: HTTP Method | F1: URL / Endpoint | G1: Headers | H1: Request Body / Parameters | I1: Preconditions | J1: Test Steps | K1: Expected Result | L1: Actual Result | M1: Status | N1: Defect ID
A2: TC-001 | B2: Booking Retrieval | C2: Get all booking IDs | D2: Positive | E2: GET | F2: https://restful-booker.herokuapp.com/booking | G2: Accept: application/json | H2: None | I2: At least one booking exists in the system. | J2: 1. Send GET request to /booking 2. Inspect response | K2: Status 200 OK; response body is a JSON array of objects each containing a 'bookingid' field | L2: As expected Result | M2: Pass
A3: TC-002 | B3: Booking Retrieval | C3: Get booking by valid ID | D3: Positive | E3: GET | F3: https://restful-booker.herokuapp.com/booking/{bookingid} | G3: Accept: application/json | H3: bookingid | I3: A booking with a known ID exists (create via POST /booking first). | J3: 1. Send GET request to /booking/{bookingid} using a valid ID 2. Inspect response | K3: Status 200 OK; response body contains firstname, lastname, totalprice, depositpaid, bookingdates, additionalneeds matching the created booking | L3: As expected Result | M3: Pass
A4: TC-003 | B4: Booking Retrieval | C4: Filter bookings by valid firstname | D4: Positive | E4: GET | F4: https://restful-booker.herokuapp.com/booking?firstname=Jim | G4: Accept: application/json | H4: firstname=Jim | I4: A booking with firstname 'Jim' exists. | J4: 1. Send GET /booking?firstname=Jim 2. Inspect returned list | K4: Status 200 OK; all returned booking IDs correspond to bookings with firstname 'Jim' when individually fetched | L4: As expected Result | M4: Pass
A5: TC-004 | B5: Booking Retrieval | C5: Filter bookings by valid lastname | D5: Positive | E5: GET | F5: https://restful-booker.herokuapp.com/booking?lastname=Brown | G5: Accept: application/json | H5: lastname=Brown | I5: A booking with lastname 'Brown' exists. | J5: 1. Send GET /booking?lastname=Brown 2. Inspect returned list | K5: Status 200 OK; returned bookings match lastname filter | L5: As expected Result | M5: Pass
A6: TC-005 | B6: Booking Retrieval | C6: Filter bookings by firstname AND lastname | D6: Positive | E6: GET | F6: https://restful-booker.herokuapp.com/booking?firstname=Jim&lastname=Brown | G6: Accept: application/json | H6: firstname=Jim, lastname=Brown | I6: Booking(s) matching both filters exist. | J6: 1. Send GET /booking?firstname=Jim&lastname=Brown 2. Inspect returned list | K6: Status 200 OK; only bookings matching both filters are returned | L6: As expected Result | M6: Pass
A7: TC-006 | B7: Booking Retrieval | C7: Filter bookings by checkin date | D7: Positive | E7: GET | F7: https://restful-booker.herokuapp.com/booking?checkin=2022-01-01 | G7: Accept: application/json | H7: checkin=2022-01-01 | I7: Booking(s) with this checkin date exist. | J7: 1. Send GET /booking?checkin=2022-01-01 2. Inspect returned list | K7: Status 200 OK; returned bookings have checkin date on/after 2022-01-01 | L7: As expected Result | M7: Pass
A8: TC-007 | B8: Booking Retrieval | C8: Filter bookings by checkout date | D8: Positive | E8: GET | F8: https://restful-booker.herokuapp.com/booking?checkout=2022-01-31 | G8: Accept: application/json | H8: checkout=2022-01-31 | I8: Booking(s) with this checkout date exist. | J8: 1. Send GET /booking?checkout=2022-01-31 2. Inspect returned list | K8: Status 200 OK; returned bookings have checkout date on/before 2022-01-31 | L8: As expected Result | M8: Pass
A9: TC-008 | B9: Booking Retrieval | C9: Filter bookings by checkin AND checkout range | D9: Positive | E9: GET | F9: https://restful-booker.herokuapp.com/booking?checkin=2022-01-01&checkout=2022-01-31 | G9: Accept: application/json | H9: checkin=2022-01-01, checkout=2022-01-31 | I9: Booking(s) within this date range exist. | J9: 1. Send GET /booking?checkin=2022-01-01&checkout=2022-01-31 2. Inspect returned list | K9: Status 200 OK; only bookings within the date range are returned | L9: As expected Result | M9: Pass
A10: TC-009 | B10: Booking Retrieval | C10: Filter bookings by checkin AND checkout range( checkin date after ( > )checkout date ) | D10: Negative | E10: GET | F10: https://restful-booker.herokuapp.com/booking?checkin=2022-01-31&checkout=2022-01-01 | G10: Accept: application/json | H10: checkin=2022-01-31, checkout=2022-01-01 | I10: Booking(s) within this date range exist. | J10: 1. Send GET /booking?checkin=2022-01-31&checkout=2022-01-01 2. Inspect returned list | K10: Bad request 400 ( invalid input data) | L10: status 200 , no booking data returned | M10: Fail | N10: DEF-001
A11: TC-010 | B11: Booking Retrieval | C11: Get booking by non-existent ID | D11: Negative | E11: GET | F11: https://restful-booker.herokuapp.com/booking/999999999 | G11: Accept: application/json | H11: bookingid=999999999 | I11: None. | J11: 1. Send GET /booking/999999999 2. Inspect response | K11: Status 404 Not Found; no booking data returned | L11: As expected Result | M11: Pass
A12: TC-011 | B12: Booking Retrieval | C12: Get booking using non-numeric ID | D12: Negative | E12: GET | F12: https://restful-booker.herokuapp.com/booking/sahar | G12: Accept: application/json | H12: bookingid=sahar | I12: None. | J12: 1. Send GET /booking/sahar 2. Inspect response | K12: Status 404 Not Found (API should reject non-numeric ID gracefully) | L12: As expected Result | M12: Pass
A13: TC-012 | B13: Booking Retrieval | C13: Search with a name that does not exist | D13: Negative | E13: GET | F13: https://restful-booker.herokuapp.com/booking?firstname=XYZ123 | G13: Accept: application/json | H13: firstname=XYZ123 | I13: None. | J13: 1. Send GET /booking?firstname=XYZ123 2. Inspect response | K13: Status 200 OK; response body is an empty array [] | L13: As expected Result | M13: Pass
A14: TC-013 | B14: Booking Retrieval | C14: Get booking with negative ID | D14: Negative | E14: GET | F14: https://restful-booker.herokuapp.com/booking/-1 | G14: Accept: application/json | H14: bookingid=-1 | I14: None. | J14: 1. Send GET /booking/-1 2. Inspect response | K14: Status 404 Not Found | L14: As expected Result | M14: Pass
A15: TC-014 | B15: Booking Retrieval | C15: Get booking with unsupported HTTP method | D15: Negative | E15: POST | F15: https://restful-booker.herokuapp.com/booking/{bookingid} | G15: Accept: application/json | H15: bookingid=<valid ID> | I15: A booking exists. | J15: 1. Send POST to /booking/{bookingid} (GET-only style endpoint misused) 2. Inspect response | K15: Status 404 or 405; endpoint does not support POST for retrieval by ID | L15: As expected Result | M15: Pass
A16: TC-015 | B16: Booking Retrieval | C16: Get booking with ID = 0 | D16: Boundary | E16: GET | F16: https://restful-booker.herokuapp.com/booking/0 | G16: Accept: application/json | H16: bookingid=0 | I16: None. | J16: 1. Send GET /booking/0 2. Inspect response | K16: Status 404 Not Found (0 is not a valid assigned booking ID) | L16: As expected Result | M16: Pass
A17: TC-016 | B17: Booking Retrieval | C17: Get booking with maximum integer ID boundary | D17: Boundary | E17: GET | F17: https://restful-booker.herokuapp.com/booking/2147483647 | G17: Accept: application/json | H17: bookingid=2147483647 (max 32-bit int) | I17: None. | J17: 1. Send GET /booking/2147483647 2. Inspect response | K17: API handles large ID gracefully; Status 404 Not Found | L17: As expected Result | M17: Pass
A18: TC-017 | B18: Booking Retrieval | C18: Filter with empty firstname value | D18: Boundary | E18: GET | F18: https://restful-booker.herokuapp.com/booking?firstname= | G18: Accept: application/json | H18: firstname= (empty string) | I18: None. | J18: 1. Send GET /booking?firstname= 2. Inspect response | K18: Status 200 OK; API either returns all bookings or an empty array — document actual behavior | L18: As expected Result | M18: Pass
A19: TC-018 | B19: Booking Retrieval | C19: Filter with different date format | D19: Boundary | E19: GET | F19: https://restful-booker.herokuapp.com/booking?checkin=01-01-2026 | G19: Accept: application/json | H19: checkin=01-01-2022,( right YYYY-MM-DD) | I19: None. | J19: 1. Send GET with different format date 2. Inspect response | K19: Bad request 400 ( invalid input data) | L19: InternalServerError 500 | M19: Fail | N19: DEF-002
A20: TC-019 | B20: Booking Retrieval | C20: Validate response schema for GET /booking/{id} | D20: Data Validation | E20: GET | F20: https://restful-booker.herokuapp.com/booking/{bookingid} | G20: Accept: application/json | H20: bookingid=<valid ID> | I20: A booking exists with known field values. | J20: 1. Send GET /booking/{bookingid} 2. Validate each field type and value in response | K20: firstname/lastname are strings; totalprice is a number; depositpaid is boolean; bookingdates.checkin/checkout are valid date strings; additionalneeds is a string or absent | L20: As expected Result | M20: Pass
A21: TC-020 | B21: Booking Retrieval | C21: Validate bookingid list contains only integers | D21: Data Validation | E21: GET | F21: https://restful-booker.herokuapp.com/booking | G21: Accept: application/json | H21: None | I21: Bookings exist in the system. | J21: 1. Send GET /booking 2. Validate each item's bookingid field type | K21: Every element in the response array has a bookingid field of type integer | L21: As expected Result | M21: Pass
A22: TC-021 | B22: Booking Retrieval | C22: Validate no unexpected/extra fields in response | D22: Data Validation | E22: GET | F22: https://restful-booker.herokuapp.com/booking/{bookingid} | G22: Accept: application/json | H22: bookingid=<valid ID> | I22: A booking exists. | J22: 1. Send GET /booking/{bookingid} 2. Compare response keys against expected schema | K22: Response contains only expected keys: firstname, lastname, totalprice, depositpaid, bookingdates, additionalneeds | L22: As expected Result | M22: Pass
A23: TC-022 | B23: Booking Retrieval | C23: Verify status code 200 for successful retrieval | D23: Status Code Validation | E23: GET | F23: https://restful-booker.herokuapp.com/booking/{bookingid} | G23: Accept: application/json | H23: bookingid=<valid ID> | I23: A booking exists. | J23: 1. Send GET /booking/{bookingid} 2. Check HTTP status code | K23: Response status code is exactly 200 | L23: As expected Result | M23: Pass
A24: TC-023 | B24: Booking Retrieval | C24: Verify status code 404 for non-existent booking | D24: Status Code Validation | E24: GET | F24: https://restful-booker.herokuapp.com/booking/999999999 | G24: Accept: application/json | H24: bookingid=999999999 | I24: None. | J24: 1. Send GET /booking/999999999 2. Check HTTP status code | K24: Response status code is exactly 404 | L24: As expected Result | M24: Pass
A25: TC-024 | B25: Booking Retrieval | C25: Verify status code 200 for GET /booking with filters returning empty results | D25: Status Code Validation | E25: GET | F25: https://restful-booker.herokuapp.com/booking?firstname=NoMatch999 | G25: Accept: application/json | H25: firstname=NoMatch999 | I25: None. | J25: 1. Send GET with a filter matching no records 2. Check HTTP status code | K25: Response status code is 200 even when result set is empty (not 404) | L25: As expected Result | M25: Pass
A26: TC-025 | B26: Booking Retrieval | C26: Validate response body matches created booking data exactly | D26: Response Body Validation | E26: GET | F26: https://restful-booker.herokuapp.com/booking/{bookingid} | G26: Accept: application/json | H26: bookingid=<ID of a booking created via POST with known data> | I26: A booking was created with known field values via POST /booking. | J26: 1. Create a booking via POST, capture request payload 2. Send GET /booking/{bookingid} 3. Compare response body field-by-field against original payload | K26: All fields in response body (firstname, lastname, totalprice, depositpaid, bookingdates, additionalneeds) exactly match the original POST payload | L26: As expected Result | M26: Pass
A27: TC-026 | B27: Booking Retrieval | C27: Validate nested bookingdates object structure | D27: Response Body Validation | E27: GET | F27: https://restful-booker.herokuapp.com/booking/{bookingid} | G27: Accept: application/json | H27: bookingid=<valid ID> | I27: A booking exists. | J27: 1. Send GET /booking/{bookingid} 2. Inspect bookingdates nested object | K27: bookingdates object contains valid 'checkin' and 'checkout' keys in YYYY-MM-DD format | M27: Pass
A28: TC-027 | B28: Booking Retrieval | C28: Verify response time for GET /booking/{id} is within SLA | D28: Response Time | E28: GET | F28: https://restful-booker.herokuapp.com/booking/{bookingid} | G28: Accept: application/json | H28: bookingid=<valid ID> | I28: A booking exists. | J28: 1. Send GET /booking/{bookingid} 2. Record response time | K28: Response time is under 1000 ms (adjust SLA threshold per project requirements) | M28: pass
A29: TC-028 | B29: Booking Update | C29: Full update (PUT) with valid token and complete data | D29: Positive | E29: PUT | F29: https://restful-booker.herokuapp.com/booking/{bookingid} | G29: Content-Type: application/json, Accept: application/json, Cookie: token=<valid_token> | H29: { "firstname": "updtaed", "lastname": "updated ", "totalprice": 103, "depositpaid": false, "bookingdates": { "checkin": "2025-08-17", "checkout": "2026-01-02" }, "additionalneeds": "updated " } | I29: A booking exists; a valid auth token has been generated via POST /auth. | J29: 1. Send PUT /booking/{bookingid} with valid token and full payload 2. Inspect response 3. GET the booking to confirm persistence | K29: Status 200 OK; response body reflects all updated fields exactly; GET confirms persisted changes and valid Token | L29: As expected Result | M29: Pass
A30: TC-029 | B30: Booking Update | C30: Partial update (PATCH) with valid token, single field | D30: Positive | E30: PATCH | F30: https://restful-booker.herokuapp.com/booking/{bookingid} | G30: Content-Type: application/json, Accept: application/json, Cookie: token=<valid_token> | H30: "firstname": "updtaed222222", | I30: A booking exists; a valid auth token has been generated. | J30: 1. Send PATCH /booking/{bookingid} updating only first name 2. Inspect response 3. GET the booking to confirm only totalprice changed | K30: Status 200 oK; first name only updated; all other fields remain unchanged | L30: As expected Result | M30: pass
A31: TC-030 | B31: Booking Update | C31: Partial update (PATCH) of bookingdates object | D31: Positive | E31: PATCH | F31: https://restful-booker.herokuapp.com/booking/{bookingid} | G31: Content-Type: application/json, Cookie: token=<valid_token> | H31: {"bookingdates":{"checkin":"2026-11-01","checkout":"2026-11-05"}} | I31: A booking exists; a valid auth token has been generated. | J31: 1. Send PATCH /booking/{bookingid} updating only bookingdates 2. Inspect response 3. GET to confirm other fields unchanged | K31: Status 200 OK; only bookingdates updated; firstname/lastname/totalprice/depositpaid/additionalneeds unchanged | L31: As expected Result | M31: pass
A32: TC-031 | B32: Booking Update | C32: Full update (PUT) using Basic Auth instead of token cookie | D32: Positive | E32: PUT | F32: https://restful-booker.herokuapp.com/booking/{bookingid} | G32: Authorization: Basic YWRtaW46cGFzc3dvcmQxMjM=, Content-Type: application/json | H32: {"firstname":"Alice","lastname":"Green","totalprice":300,"depositpaid":false,"bookingdates":{"checkin":"2026-08-01","checkout":"2026-08-10"},"additionalneeds":"None"} | I32: A booking exists. | J32: 1. Send PUT /booking/{bookingid} using Basic Auth header instead of Cookie token 2. Inspect response | K32: Status 200 OK; Basic Auth accepted as a valid alternative to token cookie , and data updated | L32: As expected Result | M32: Pass
A33: TC-032 | B33: Booking Update | C33: Update without authorization (no token/header) | D33: Negative | E33: PUT | F33: https://restful-booker.herokuapp.com/booking/{bookingid} | G33: Content-Type: application/json (no Cookie/Authorization) | H33: { "firstname": "without auth - no updated", "lastname": "basic auth ", "totalprice": 123, "depositpaid": false, "bookingdates": { "checkin": "2025-08-16", "checkout": "2026-01-04" }, "additionalneeds": "basic auth " } | I33: A booking exists. | J33: 1. Send PUT /booking/{bookingid} with no auth header 2. Inspect response 3. GET to confirm data unchanged | K33: Status 403 Forbidden; booking data remains unchanged | L33: As expected Result | M33: pass
A34: TC-033 | B34: Booking Update | C34: Update with invalid or expired token | D34: Negative | E34: PUT | F34: https://restful-booker.herokuapp.com/booking/{bookingid} | G34: Cookie: token=invalidtoken123, Content-Type: application/json | H34: { "firstname": "invalid auth - no updated", "lastname": "basic auth ", "totalprice": 123, "depositpaid": false, "bookingdates": { "checkin": "2025-08-16", "checkout": "2026-01-04" }, "additionalneeds": "basic auth " } | I34: A booking exists. | J34: 1. Send PUT /booking/{bookingid} with a malformed/invalid token 2. Inspect response | K34: Status 403 Forbidden | L34: As expected Result | M34: PASS
A35: TC-034 | B35: Booking Update | C35: Update non-existent booking ID | D35: Negative | E35: PUT | F35: https://restful-booker.herokuapp.com/booking/999999999 | G35: Cookie: token=<valid_token>, Content-Type: application/json | H35: { "firstname": "NON- EXIST ID ", "lastname": "basic auth ", "totalprice": 123, "depositpaid": false, "bookingdates": { "checkin": "2025-08-16", "checkout": "2026-01-04" }, "additionalneeds": "basic auth " } | I35: None; ID does not correspond to any booking. | J35: 1. Send PUT /booking/999999999 with a valid token and full payload 2. Inspect response | K35: Status 405 Method Not Allowed | L35: As expected Result | M35: Pass
A36: TC-035 | B36: Booking Update | C36: PUT with invalid JSON body | D36: Negative | E36: PUT | F36: https://restful-booker.herokuapp.com/booking/{bookingid} | G36: Cookie: token=<valid_token>, Content-Type: application/json | H36: { "firstname": 9999999, "lastname": *********, "totalprice": &&&&&&&&&, "depositpaid": false, "bookingdates": { "checkin": "2025-08-16", "checkout": "2026-01-04" }, "additionalneeds": "basic auth " } | I36: A booking exists; a valid auth token has been generated. | J36: 1. Send PUT /booking/{bookingid} with syntactically broken JSON 2. Inspect response | K36: Status 400 Bad Request | L36: As expected Result | M36: Pass
A37: TC-036 | B37: Booking Update | C37: PUT with missing required fields | D37: Negative | E37: PUT | F37: https://restful-booker.herokuapp.com/booking/{bookingid} | G37: Cookie: token=<valid_token>, Content-Type: application/json | H37: {"firstname":"OnlyFirstName"} | I37: A booking exists; a valid auth token has been generated. | J37: 1. Send PUT /booking/{bookingid} omitting lastname, totalprice, depositpaid, bookingdates 2. Inspect response | K37: Bad request 400 | L37: As expected Result | M37: Pass
A38: TC-037 | B38: Booking Update | C38: PATCH & put with completely empty body | D38: Boundary | E38: PATCH | F38: https://restful-booker.herokuapp.com/booking/{bookingid} | G38: Cookie: token=<valid_token>, Content-Type: application/json | H38: {} | I38: A booking exists; a valid auth token has been generated. | J38: 1. Send PATCH /booking/{bookingid} with an empty JSON object 2. Inspect response | K38: patch :Status 200 OK; no fields changed | put :status Bad Request . | L38: As expected Result | M38: Pass
A39: TC-038 | B39: Booking Update | C39: PUT with totalprice at boundary value (0) | D39: Boundary | E39: PUT | F39: https://restful-booker.herokuapp.com/booking/{bookingid} | G39: Cookie: token=<valid_token>, Content-Type: application/json | H39: { "firstname": "Sally", "lastname": "Brown", "totalprice": 0, "depositpaid": true, "bookingdates": { "checkin": "2022-11-08", "checkout": "2024-04-25" } } | I39: A booking exists; a valid auth token has been generated. | J39: 1. Send PUT with totalprice = 0 2. Inspect response | K39: Status 200 OK; totalprice of 0 accepted as valid boundary value | L39: As expected Result | M39: Pass
A40: TC-039 | B40: Booking Update | C40: PUT with negative totalprice | D40: Boundary | E40: PUT | F40: https://restful-booker.herokuapp.com/booking/{bookingid} | G40: Cookie: token=<valid_token>, Content-Type: application/json | H40: { "firstname": "Sally", "lastname": "Brown", "totalprice": -300, "depositpaid": true, "bookingdates": { "checkin": "2022-11-08", "checkout": "2024-04-25" } } | I40: A booking exists; a valid auth token has been generated. | J40: 1. Send PUT with totalprice = -300 2. Inspect response | K40: Document actual behavior; flag as bug if API accepts negative totalprice without validation | L40: Status 200 OK; totalprice of -330 accepted as valid value | M40: Fail | N40: DEF-003
...

Sheet Bug Report 
A1: Defect ID | B1: Test ID | C1: Module / Endpoint | D1: Defect Title | E1: Defect description | F1: Enviroments | G1: steps | H1: Expected Result | I1: Actual Result | J1: Severity | K1: Priority | L1: Test Type | M1: Defect Summary & Impact
A2: DEF-001 | B2: TC-GET-008 | C2: Booking Retrieval-GET /booking/ | D2: Booking API returns 200 OK instead of 400 Bad Request for invalid date range | E2: The GET /booking endpoint accepts an invalid date range where the check-in date is later than the checkout date. | F2: Environment: QA / Test API: Restful Booker Endpoint: GET /booking Method: GET Request: /booking?checkin=2022-01-31&checkout=2022-01-01,https://restful-booker.herokuapp.com/booking Header: Accept: application/json | G2: 1. Send GET /booking?checkin=2022-01-31&checkout=2022-01-01 2. Inspect returned list | H2: Bad request 400 ( invalid input data) | I2: status 200 , no booking data returned | J2: Medium | K2: Medium | L2: Negative | M2: Check-in date after check-out date returns 200 OK
A3: DEF-002 | B3: TC-GET-018 | C3: Booking Retrieval-GET /booking/ | D3: Booking API returns 500 Internal Server Error for invalid check-in date format( Date structure) | E3: The GET /booking endpoint does not properly handle an invalid date format for the checkin parameter | F3: Environment: QA / Test API: Restful Booker Endpoint: GET /booking Method: GET Request: /booking?checkin=01-01-2026 Header: Accept: application/json Expected Date Format: YYYY-MM-DD Invalid Date Format: DD-MM-YYYY | G3: 1. Send GET with different format date 2. Inspect response | H3: Bad request 400 ( invalid input data) | I3: InternalServerError 500 | J3: High | K3: High | L3: Boundary | M3: Non-standard date format triggers HTTP 500 Error
A4: DEF-003 | B4: TC-PUT-012 | C4: Booking Update -PUT /booking/{id} | D4: Booking Update API accepts negative totalprice without validation | E4: The PUT /booking/{bookingid} endpoint accepts a negative value for the totalprice field without performing input validation. When a booking is updated with a negative totalprice (e.g., -300 or -50), the API returns HTTP 200 OK and stores the negative price as a valid booking value. | F4: Environment: QA / Test API: Restful Booker Endpoint: PUT /booking/{bookingid} Method: PUT Authentication: Valid token cookie Content-Type: application/json Input: totalprice = -300 | G4: 1. Send PUT with totalprice = -300 2. Inspect response | H4: Document actual behavior; flag as bug if API accepts negative totalprice without validation | I4: Status 200 OK; totalprice of -330 accepted as valid value | J4: High | K4: High | L4: Boundary | M4: Negative totalprice accepted without validation
A5: DEF-004 | B5: TC-PUT-013 | C5: Booking Update- PUT /booking/{id} | D5: Booking Update API accepts checkout date earlier than check-in date | E5: The PUT /booking/{bookingid} endpoint accepts an invalid booking date range where the checkout date is earlier than the check-in date. | F5: Environment: QA / Test API: Restful Booker Endpoint: PUT /booking/{bookingid} Method: PUT Authentication: Valid token cookie Content-Type: application/json Check-in: 2026-11-08 Checkout: 2024-04-25 | G5: 1. Send PUT with checkout earlier than checkin 2. Inspect response | H5: Document actual behavior; flag as bug if accepted without validation error | I5: Status 200 OK; checkin& checkout updated | J5: High | K5: High | L5: Boundary | M5: Checkout date prior to checkin date accepted
A6: DEF-005 | B6: TC-PUT-015 | C6: Booking Update/PUT /booking/{id} | D6: Booking Update API does not handle invalid data types correctly | E6: The PUT /booking/{bookingid} endpoint is tested with invalid data types in multiple fields, including firstname, lastname, totalprice, depositpaid, checkin, and checkout. | F6: Environment: QA / Test API: Restful Booker Endpoint: PUT /booking/{bookingid} Method: PUT Authentication: Valid token cookie Content-Type: application/json | G6: 1. Send PUT with totalprice as string and depositpaid as string 2. Inspect response | H6: API 400 Bad Request, and the booking should not be successfully updated. | I6: InternalServerError 500 | J6: High | K6: High | L6: Data Validation | M6: Invalid field data types bypass schema validation . Sending string types for numbers/booleans and numbers for strings is not handled gracefully with 400 Bad Request.
A7: DEF-006 | B7: TC-054 | C7: Booking Retrieval-GET /booking/ | D7: GET Booking Filter returns 500 instead of 400 for invalid check-in date | E7: The Booking Retrieval API returns 500 Internal Server Error when an invalid check-in date (2026-13-45) is provided. The API should validate the input and return 400 Bad Request instead of exposing a server-side error | F7: Environment: QA / Test API: Restful Booker Endpoint: GET /booking Method: GET Request: /booking?checkin=2026-13-45 Header: Accept: application/json Expected Date Format: YYYY-MM-DD Invalid Date : 2026-13-45 | G7: 1. Send GET with invalid date 2. Inspect response | H7: Bad request 400 ( invalid input data) | I7: InternalServerError 500 | J7: Medium | K7: Medium | L7: Validation | M7: Invalid check-in date returns 500 instead of 400 Bad Request.Incorrect error handling and API validation.
A8: DEF-007 | B8: TC-DEL-001 | C8: Booking Deletion - DELETE /booking/{id} | D8: DELETE Booking API returns 201 Created instead of 204 No Content | E8: The DELETE endpoint successfully removes the booking from the database but it returns an incorrect HTTP status code 201 Created and the text "Created" in the response body It should return a standard 204 status with no text | F8: Environment: QA / Test API: Restful Booker Endpoint: DELETE /booking/{bookingid} Method: DELETE Authentication: Valid token cookie | G8: 1. Send DELETE request to a valid booking ID 2. Inspect HTTP status code and response body text | H8: 204 No Content (Empty response body) | I8: Status 201 Created | J8: High | K8: High | L8: Validation | M8: Wrong status code. Returning a creation status 201 for a DELETE action breaks standard API rules and will confuse frontend applications or other developers using this API
A9: DEF-008 | B9: TC-068, TC-069, TC-070, TC-074 | C9: Auth - POST /auth | D9: Auth API returns 200 OK instead of 401 Unauthorized for invalid credentials | E9: The POST /auth endpoint accepts requests with a wrong password, wrong username, both wrong, or empty string credentials, and returns HTTP 200 with no token, instead of rejecting the request with HTTP 401 Unauthorized. | F9: Environment: QA / Test API: Restful Booker Endpoint: POST /auth Method: POST https://restful-booker.herokuapp.com/auth Header: Content-Type: application/json | G9: 1. Send POST /auth with invalid credentials (wrong password / wrong username / both wrong / empty strings) 2. Inspect status code and body | H9: Status 401 Unauthorized, no token in response | I9: Status 200 OK, no token in response (correct behavior but wrong status code) | J9: High | K9: High | L9: Negative | M9: Clients relying on the HTTP status code to detect a failed login will treat this as a successful call, which can break authentication flows and error handling downstream.
A10: DEF-009 | B10: TC-071, TC-072, TC-073 | C10: Auth - POST /auth | D10: Auth API returns 200 OK instead of 400 Bad Request for missing required fields, with no error message | E10: Omitting the 'username' field, the 'password' field, or sending a completely empty JSON body still returns HTTP 200 with no token and no descriptive error message, instead of HTTP 400 Bad Request with a message identifying the missing field(s). | F10: Environment: QA / Test API: Restful Booker Endpoint: POST /auth Method: POST https://restful-booker.herokuapp.com/auth Header: Content-Type: application/json | G10: 1. Send POST /auth missing 'username' and/or 'password' (or an empty body {}) 2. Inspect status code and body | H10: Status 400 Bad Request; response mentions the missing field(s) | I10: Status 200 OK; no token, no error message about the missing field(s); server does not crash | J10: High | K10: Medium | L10: Negative / Boundary | M10: Silent failures with no error message make it difficult for API consumers to debug integration issues and distinguish a malformed request from any other failure.
A11: DEF-010 | B11: TC-075 | C11: Auth - POST /auth | D11: Auth API accepts invalid data type for 'username' without validation | E11: Sending 'username' as a number instead of a string is accepted by the endpoint and returns HTTP 200, instead of being rejected with HTTP 400 Bad Request. | F11: Environment: QA / Test API: Restful Booker Endpoint: POST /auth Method: POST https://restful-booker.herokuapp.com/auth Header: Content-Type: application/json | G11: 1. Send POST /auth with 'username' as a number (e.g. 12345) 2. Inspect status code and body | H11: Status 400 Bad Request; request rejected due to invalid data type | I11: Status 200 OK; request accepted, no data type validation performed | J11: Medium | K11: Medium | L11: Boundary | M11: Lack of data type validation may allow malformed data through the API, increasing the risk of unexpected errors in downstream processing.
A12: DEF-011 | B12: TC-078 | C12: Auth - POST /auth | D12: Auth API does not enforce/validate the Content-Type header | E12: Sending a request with a missing or incorrect Content-Type header (e.g. text/plain instead of application/json) returns HTTP 400 Bad Request instead of HTTP 415 Unsupported Media Type | F12: Environment: QA / Test API: Restful Booker Endpoint: POST /auth Method: POST https://restful-booker.herokuapp.com/auth Header: Content-Type: application/xml | G12: 1. Send POST /auth with a valid body but missing/incorrect 'Content-Type' header 2. Inspect status code and body | H12: Status 415 Unsupported Media Type | I12: 400 Bad Request; | J12: Low | K12: Low | L12: Negative | M12: Minor - the API is overly lenient with headers, which does not follow REST standards for content negotiation, but it does not block core functionality.
... A19: DEF-018 | B19: TC-052 | C19: End-to-End | D19: POST Create Booking API returns 200 OK instead of 201 Created | E19: The Create Booking API returns 200 OK when a new booking is successfully created. According to the expected REST API behavior, creating a new resource should return 201 Created. | F19: Environment: QA / Test API: Restful Booker Endpoint: POST /booking Method: POST https://restful-booker.herokuapp.com/booking Header: Content-Type: application/json | G19: non | H19: 1. POST /booking to create a booking with firstname='sahar', lastname='qat' 2. Capture returned bookingid 3. GET /booking?firstname=sahar&lastname=FilterTest 4. Verify the captured bookingid appears in the returned list, STATUS CODD 201 | I19: The newly created booking's ID is present in the filtered results, confirming create-then-search consistency, BUT STATUS CODE 200 | J19: low | K19: low | L19: end | M19: NA
